Seed set to 20241203
Using cache found in /root/.cache/torch/hub/facebookresearch_dinov2_main
/root/.cache/torch/hub/facebookresearch_dinov2_main/dinov2/layers/swiglu_ffn.py:43: UserWarning: xFormers is available (SwiGLU)
  warnings.warn("xFormers is available (SwiGLU)")
/root/.cache/torch/hub/facebookresearch_dinov2_main/dinov2/layers/attention.py:27: UserWarning: xFormers is available (Attention)
  warnings.warn("xFormers is available (Attention)")
/root/.cache/torch/hub/facebookresearch_dinov2_main/dinov2/layers/block.py:33: UserWarning: xFormers is available (Block)
  warnings.warn("xFormers is available (Block)")
Using 16bit Automatic Mixed Precision (AMP)
GPU available: True (cuda), used: True
TPU available: False, using: 0 TPU cores
HPU available: False, using: 0 HPUs
You are using a CUDA device ('NVIDIA GeForce RTX 4090') that has Tensor Cores. To properly utilize them, you should set `torch.set_float32_matmul_precision('medium' | 'high')` which will trade-off precision for performance. For more details, read https://pytorch.org/docs/stable/generated/torch.set_float32_matmul_precision.html#torch.set_float32_matmul_precision
LOCAL_RANK: 0 - CUDA_VISIBLE_DEVICES: [0]
[rank: 0] Received SIGTERM: 15
Traceback (most recent call last):
  File "/venv/main/lib/python3.12/site-packages/lightning/pytorch/trainer/call.py", line 48, in _call_and_handle_interrupt
    return trainer_fn(*args, **kwargs)
           ^^^^^^^^^^^^^^^^^^^^^^^^^^^
  File "/venv/main/lib/python3.12/site-packages/lightning/pytorch/trainer/trainer.py", line 599, in _fit_impl
    self._run(model, ckpt_path=ckpt_path)
  File "/venv/main/lib/python3.12/site-packages/lightning/pytorch/trainer/trainer.py", line 1012, in _run
    results = self._run_stage()
              ^^^^^^^^^^^^^^^^^
  File "/venv/main/lib/python3.12/site-packages/lightning/pytorch/trainer/trainer.py", line 1056, in _run_stage
    self.fit_loop.run()
  File "/venv/main/lib/python3.12/site-packages/lightning/pytorch/loops/fit_loop.py", line 216, in run
    self.advance()
  File "/venv/main/lib/python3.12/site-packages/lightning/pytorch/loops/fit_loop.py", line 455, in advance
    self.epoch_loop.run(self._data_fetcher)
  File "/venv/main/lib/python3.12/site-packages/lightning/pytorch/loops/training_epoch_loop.py", line 153, in run
    self.on_advance_end(data_fetcher)
  File "/venv/main/lib/python3.12/site-packages/lightning/pytorch/loops/training_epoch_loop.py", line 410, in on_advance_end
    raise SIGTERMException
lightning.pytorch.utilities.exceptions.SIGTERMException

During handling of the above exception, another exception occurred:

Traceback (most recent call last):
  File "/workspace/text-to-image-retrivial/train.py", line 160, in <module>
    train(batch_size=args.bs, lr=args.lr, dim=args.dim, dev=args.dev)
  File "/workspace/text-to-image-retrivial/train.py", line 147, in train
    trainer.fit(model, train_dataloader, val_dataloader)
  File "/venv/main/lib/python3.12/site-packages/lightning/pytorch/trainer/trainer.py", line 561, in fit
    call._call_and_handle_interrupt(
  File "/venv/main/lib/python3.12/site-packages/lightning/pytorch/trainer/call.py", line 69, in _call_and_handle_interrupt
    trainer._teardown()
  File "/venv/main/lib/python3.12/site-packages/lightning/pytorch/trainer/trainer.py", line 1035, in _teardown
    self.strategy.teardown()
  File "/venv/main/lib/python3.12/site-packages/lightning/pytorch/strategies/strategy.py", line 532, in teardown
    _optimizers_to_device(self.optimizers, torch.device("cpu"))
  File "/venv/main/lib/python3.12/site-packages/lightning/fabric/utilities/optimizer.py", line 27, in _optimizers_to_device
    _optimizer_to_device(opt, device)
  File "/venv/main/lib/python3.12/site-packages/lightning/fabric/utilities/optimizer.py", line 41, in _optimizer_to_device
    v[key] = move_data_to_device(val, device)
             ^^^^^^^^^^^^^^^^^^^^^^^^^^^^^^^^
  File "/venv/main/lib/python3.12/site-packages/lightning/fabric/utilities/apply_func.py", line 110, in move_data_to_device
    return apply_to_collection(batch, dtype=_TransferableDataType, function=batch_to)
           ^^^^^^^^^^^^^^^^^^^^^^^^^^^^^^^^^^^^^^^^^^^^^^^^^^^^^^^^^^^^^^^^^^^^^^^^^^
  File "/venv/main/lib/python3.12/site-packages/lightning_utilities/core/apply_func.py", line 66, in apply_to_collection
    return function(data, *args, **kwargs)
           ^^^^^^^^^^^^^^^^^^^^^^^^^^^^^^^
  File "/venv/main/lib/python3.12/site-packages/lightning/fabric/utilities/apply_func.py", line 104, in batch_to
    data_output = data.to(device, **kwargs)
                  ^^^^^^^^^^^^^^^^^^^^^^^^^
  File "/venv/main/lib/python3.12/site-packages/torch/utils/data/_utils/signal_handling.py", line 73, in handler
    _error_if_any_worker_fails()
RuntimeError: DataLoader worker (pid 27078) is killed by signal: Terminated. 
Traceback (most recent call last):
  File "/usr/lib/python3.12/weakref.py", line 666, in _exitfunc
    f()
  File "/usr/lib/python3.12/weakref.py", line 590, in __call__
    return info.func(*info.args, **(info.kwargs or {}))
           ^^^^^^^^^^^^^^^^^^^^^^^^^^^^^^^^^^^^^^^^^^^^
  File "/venv/main/lib/python3.12/site-packages/urllib3/connectionpool.py", line 1174, in _close_pool_connections
    conn = pool.get(block=False)
           ^^^^^^^^^^^^^^^^^^^^^
  File "/usr/lib/python3.12/queue.py", line 182, in get
    self.not_full.notify()
  File "/usr/lib/python3.12/threading.py", line 404, in notify
    if not self._is_owned():
           ^^^^^^^^^^^^^^^^
  File "/usr/lib/python3.12/threading.py", line 314, in _is_owned
    def _is_owned(self):

  File "/venv/main/lib/python3.12/site-packages/torch/utils/data/_utils/signal_handling.py", line 73, in handler
    _error_if_any_worker_fails()
RuntimeError: DataLoader worker (pid 26997) is killed by signal: Terminated. 
